Workbook

Sheet Summary Table
B3: Value at Risk (VaR)
B4: 1 Day VaR @ | C4: 99% CI | D4: 95% CI | E4: 90% CI
B5: Variance Covariance | C5: ='Variance Covariance'!H12 -> -39803.31 | D5: ='Variance Covariance'!I12 -> -27700.756 | E5: ='Variance Covariance'!J12 -> -21248.929
B6: Historical Simulation | C6: ='Historical Simulation'!$M$16 -> -53920.453 | D6: ='Historical Simulation'!$N$16 -> -25997.085 | E6: ='Historical Simulation'!$O$16 -> -14989.714
B7: Monte Carlo Simulation | C7: ='Monte Carlo Simulation'!L13 -> -38068.767 | D7: ='Monte Carlo Simulation'!M13 -> -29734.167 | E7: ='Monte Carlo Simulation'!N13 -> -23804.262
B10: Value at Risk (VaR) Backtesting - Traffic Light Approach
B11: 1 Day VaR @ | C11: 99% CI | D11: Backtest
B12: Variance Covariance | C12: ='Backtesting (Traffic Light)'!L17 -> 5 | D12: {=_xlfn.IFS(C12<5, "Green Zone", C12<10, "Yellow Zone", C12>=10, "Red Zone")} -> Yellow Zone
B13: Historical Simulation | C13: ='Backtesting (Traffic Light)'!L18 -> 2 | D13: {=_xlfn.IFS(C13<5, "Green Zone", C13<10, "Yellow Zone", C13>=10, "Red Zone")} -> Green Zone
B14: Monte Carlo Simulation | C14: ='Backtesting (Traffic Light)'!L19 -> 6 | D14: {=_xlfn.IFS(C14<5, "Green Zone", C14<10, "Yellow Zone", C14>=10, "Red Zone")} -> Yellow Zone
B17: 1 day VaR Backtest @ 99% CI | C17: Variance Covariance | D17: Historical Method | E17: Monte Carlo Method
B18: p (expected probability (CI)) | C18: ='Backtesting (Kupiec)'!L15 -> 0.01 | D18: ='Backtesting (Kupiec)'!M15 -> 0.01 | E18: ='Backtesting (Kupiec)'!N15 -> 0.01
B19: x (no. of violation) | C19: ='Backtesting (Kupiec)'!L16 -> 5 | D19: ='Backtesting (Kupiec)'!M16 -> 2 | E19: ='Backtesting (Kupiec)'!N16 -> 6
B20: n (total no. of observation) | C20: ='Backtesting (Kupiec)'!L17 -> 248 | D20: ='Backtesting (Kupiec)'!M17 -> 248 | E20: ='Backtesting (Kupiec)'!N17 -> 248
B21: p^​ (observed probability) | C21: ='Backtesting (Kupiec)'!L18 -> 0.02016129 | D21: ='Backtesting (Kupiec)'!M18 -> 0.0080645161 | E21: ='Backtesting (Kupiec)'!N18 -> 0.024193548
B22: LR (Likelihood ratio) | C22: ='Backtesting (Kupiec)'!L19 -> 1.9977476 | D22: ='Backtesting (Kupiec)'!M19 -> 0.10049229 | E22: ='Backtesting (Kupiec)'!N19 -> 3.6127198
B23: p value | C23: ='Backtesting (Kupiec)'!L20 -> 0.15753315 | D23: ='Backtesting (Kupiec)'!M20 -> 0.75123967 | E23: ='Backtesting (Kupiec)'!N20 -> 0.057339275
B24: p value > 5% | C24: Reliable | D24: Reliable | E24: Reliable
B26: Expected Shortfall | C26: Variance Covariance | D26: Historical Method | E26: Monte Carlo Method
B27: ES @ | C27: 99% CI | D27: 95% CI | E27: 90% CI
B28: Historical Simulation | C28: ='Historical Simulation'!M17 -> -83704.074 | D28: ='Historical Simulation'!N17 -> -43332.589 | E28: ='Historical Simulation'!O17 -> -31732.783
B29: Monte Carlo Simulation | C29: ='Monte Carlo Simulation'!L14 -> -45314.428 | D29: ='Monte Carlo Simulation'!M14 -> -35152.795 | E29: ='Monte Carlo Simulation'!N14 -> -30929.008

Sheet Variance Covariance
B4: Assumption | L4: Historical Data | Q4: Daily Returns | V4: Portfolio Daily Returns
B5: Portfolio | C5: JPM | D5: MS | E5: BAC | G5: VaR Using Variance Covariance Method | L5: Date | M5: JPM | N5: MS | O5: BAC | Q5: Date | R5: JPM | S5: MS | T5: BAC | V5: Date | W5: Return
B6: Weights | C6: 0.3 | D6: 0.4 | E6: 0.3 | G6: Mean | H6: =C12 -> 0.0015099525 | I6: =H6 -> 0.0015099525 | J6: =H6 -> 0.0015099525 | L6: 45597 | M6: =Data!B3 -> 218.31844 | N6: =Data!H3 -> 113.66718 | O6: =Data!N3 -> 40.799843 | Q6: 45597 | V6: 45597
B7: Investment Amt. | C7: 1000000 | G7: Std. Dev | H7: =C24 -> 0.01775885 | I7: =H7 -> 0.01775885 | J7: =H7 -> 0.01775885 | L7: 45600 | M7: =Data!B4 -> 215.22394 | N7: =Data!H4 -> 112.97652 | O7: =Data!N4 -> 40.379734 | Q7: 45600 | R7: =(M7/M6)-1 -> -0.014174239 | S7: =(N7/N6)-1 -> -0.0060761475 | T7: =(O7/O6)-1 -> -0.010296824 | V7: 45600 | W7: =SUMPRODUCT(R7:T7,$C$6:$E$6) -> -0.0097717779
B8: Stocks Value | C8: =C7*C6 -> 300000 | D8: =C7*D6 -> 400000 | E8: =C7*E6 -> 300000 | G8: CI | H8: 0.99 | I8: 0.95 | J8: 0.9 | L8: 45601 | M8: =Data!B5 -> 216.89848 | N8: =Data!H5 -> 114.60104 | O8: =Data!N5 -> 40.917088 | Q8: 45601 | R8: =(M8/M7)-1 -> 0.0077804788 | S8: =(N8/N7)-1 -> 0.014379265 | T8: =(O8/O7)-1 -> 0.013307505 | V8: 45601 | W8: =SUMPRODUCT(R8:T8,$C$6:$E$6) -> 0.012078101
G9: Alpha | H9: =1-H8 -> 0.01 | I9: =1-I8 -> 0.05 | J9: =1-J8 -> 0.1 | L9: 45602 | M9: =Data!B6 -> 241.93843 | N9: =Data!H6 -> 127.90842 | O9: =Data!N6 -> 44.365925 | Q9: 45602 | R9: =(M9/M8)-1 -> 0.11544547 | S9: =(N9/N8)-1 -> 0.11611913 | T9: =(O9/O8)-1 -> 0.084288435 | V9: 45602 | W9: =SUMPRODUCT(R9:T9,$C$6:$E$6) -> 0.10636782
G10: Z Value | H10: =_xlfn.NORM.S.INV(H9) -> -2.3263479 | I10: =_xlfn.NORM.S.INV(I9) -> -1.6448536 | J10: =_xlfn.NORM.S.INV(J9) -> -1.2815516 | L10: 45603 | M10: =Data!B7 -> 231.47981 | N10: =Data!H7 -> 124.94151 | O10: =Data!N7 -> 43.740643 | Q10: 45603 | R10: =(M10/M9)-1 -> -0.043228429 | S10: =(N10/N9)-1 -> -0.023195591 | T10: =(O10/O9)-1 -> -0.014093751 | V10: 45603 | W10: =SUMPRODUCT(R10:T10,$C$6:$E$6) -> -0.02647489
G11: Portfolio Value | H11: =1000000 -> 1000000 | I11: =H11 -> 1000000 | J11: =I11 -> 1000000 | L11: 45604 | M11: =Data!B8 -> 232.06737 | N11: =Data!H8 -> 126.00179 | O11: =Data!N8 -> 44.092361 | Q11: 45604 | R11: =(M11/M10)-1 -> 0.0025382556 | S11: =(N11/N10)-1 -> 0.008486271 | T11: =(O11/O10)-1 -> 0.0080410091 | V11: 45604 | W11: =SUMPRODUCT(R11:T11,$C$6:$E$6) -> 0.0065682878
B12: Portfolio Mean | C12: =AVERAGE(W7:W254) -> 0.0015099525 | G12: 1 Day VaR | H12: =(H6+H7*H10)*H11 -> -39803.31 | I12: =(I6+I7*I10)*I11 -> -27700.756 | J12: =(J6+J7*J10)*J11 -> -21248.929 | L12: 45607 | M12: =Data!B9 -> 234.32947 | N12: =Data!H9 -> 129.88313 | O12: =Data!N9 -> 45.020523 | Q12: 45607 | R12: =(M12/M11)-1 -> 0.0097476015 | S12: =(N12/N11)-1 -> 0.030803848 | T12: =(O12/O11)-1 -> 0.021050395 | V12: 45607 | W12: =SUMPRODUCT(R12:T12,$C$6:$E$6) -> 0.021560938
L13: 45608 | M13: =Data!B10 -> 234.59389 | N13: =Data!H10 -> 128.70609 | O13: =Data!N10 -> 44.80558 | Q13: 45608 | R13: =(M13/M12)-1 -> 0.0011284093 | S13: =(N13/N12)-1 -> -0.0090623602 | T13: =(O13/O12)-1 -> -0.0047743322 | V13: 45608 | W13: =SUMPRODUCT(R13:T13,$C$6:$E$6) -> -0.0047187209
B14: OR | L14: 45609 | M14: =Data!B11 -> 236.16072 | N14: =Data!H11 -> 129.14383 | O14: =Data!N11 -> 44.81535 | Q14: 45609 | R14: =(M14/M13)-1 -> 0.0066789187 | S14: =(N14/N13)-1 -> 0.0034011146 | T14: =(O14/O13)-1 -> 0.00021804069 | V14: 45609 | W14: =SUMPRODUCT(R14:T14,$C$6:$E$6) -> 0.0034295336
G15: Covariance Matrix | L15: 45610 | M15: =Data!B12 -> 236.856 | N15: =Data!H12 -> 128.8228 | O15: =Data!N12 -> 44.844658 | Q15: 45610 | R15: =(M15/M14)-1 -> 0.0029441051 | S15: =(N15/N14)-1 -> -0.0024858304 | T15: =(O15/O14)-1 -> 0.00065397948 | V15: 45610 | W15: =SUMPRODUCT(R15:T15,$C$6:$E$6) -> 8.5093195e-05
C16: JPM | D16: MS | E16: BAC | H16: JPM | I16: MS | J16: BAC | L16: 45611 | M16: =Data!B13 -> 240.22469 | N16: =Data!H13 -> 130.40842 | O16: =Data!N13 -> 45.675114 | Q16: 45611 | R16: =(M16/M15)-1 -> 0.014222493 | S16: =(N16/N15)-1 -> 0.012308513 | T16: =(O16/O15)-1 -> 0.0185185 | V16: 45611 | W16: =SUMPRODUCT(R16:T16,$C$6:$E$6) -> 0.014745703
B17: Mean Return of Stock | C17: =AVERAGE(R7:R254) -> 0.0015504217 | D17: =AVERAGE(S7:S254) -> 0.0016997955 | E17: =AVERAGE(T7:T254) -> 0.0012163593 | G17: JPM | H17: =VARP('Variance Covariance'!$R$7:$R$254) -> 0.00028798903 | I17: =H18 -> 0.00030641082 | J17: =H19 -> 0.00024532713 | L17: 45614 | M17: =Data!B14 -> 239.95049 | N17: =Data!H14 -> 130.13605 | O17: =Data!N14 -> 45.645809 | Q17: 45614 | R17: =(M17/M16)-1 -> -0.0011414332 | S17: =(N17/N16)-1 -> -0.0020885875 | T17: =(O17/O16)-1 -> -0.0006415858 | V17: 45614 | W17: =SUMPRODUCT(R17:T17,$C$6:$E$6) -> -0.0013703407
B18: Weights | C18: =C6 -> 0.3 | D18: =D6 -> 0.4 | E18: =E6 -> 0.3 | G18: MS | H18: 0.00030641082 | I18: =VARP('Variance Covariance'!$S$7:$S$254) -> 0.00043054374 | J18: =I19 -> 0.00031100676 | L18: 45615 | M18: =Data!B15 -> 238.0507 | N18: =Data!H15 -> 128.63802 | O18: =Data!N15 -> 45.342934 | Q18: 45615 | R18: =(M18/M17)-1 -> -0.0079173846 | S18: =(N18/N17)-1 -> -0.011511273 | T18: =(O18/O17)-1 -> -0.0066353412 | V18: 45615 | W18: =SUMPRODUCT(R18:T18,$C$6:$E$6) -> -0.0089703271
B19: Mean Return of Portfolio | C19: =SUMPRODUCT(C17:E17,C18:E18) -> 0.0015099525 | G19: BAC | H19: 0.00024532713 | I19: 0.00031100676 | J19: =VARP('Variance Covariance'!$T$7:$T$254) -> 0.00031368477 | L19: 45616 | M19: =Data!B16 -> 235.78859 | N19: =Data!H16 -> 128.103 | O19: =Data!N16 -> 45.000984 | Q19: 45616 | R19: =(M19/M18)-1 -> -0.0095026624 | S19: =(N19/N18)-1 -> -0.0041591043 | T19: =(O19/O18)-1 -> -0.0075414058 | V19: 45616 | W19: =SUMPRODUCT(R19:T19,$C$6:$E$6) -> -0.0067768622
L20: 45617 | M20: =Data!B17 -> 239.6861 | N20: =Data!H17 -> 131.3131 | O20: =Data!N17 -> 45.391781 | Q20: 45617 | R20: =(M20/M19)-1 -> 0.016529666 | S20: =(N20/N19)-1 -> 0.025058729 | T20: =(O20/O19)-1 -> 0.0086841803 | V20: 45617 | W20: =SUMPRODUCT(R20:T20,$C$6:$E$6) -> 0.017587646
L21: 45618 | M21: =Data!B18 -> 243.39754 | N21: =Data!H18 -> 131.02126 | O21: =Data!N18 -> 45.919369 | Q21: 45618 | R21: =(M21/M20)-1 -> 0.01548459 | S21: =(N21/N20)-1 -> -0.0022224714 | T21: =(O21/O20)-1 -> 0.011622983 | V21: 45618 | W21: =SUMPRODUCT(R21:T21,$C$6:$E$6) -> 0.0072432834
L22: 45621 | M22: =Data!B19 -> 245.10147 | N22: =Data!H19 -> 130.0193 | O22: =Data!N19 -> 46.407871 | Q22: 45621 | R22: =(M22/M21)-1 -> 0.0070006202 | S22: =(N22/N21)-1 -> -0.0076472563 | T22: =(O22/O21)-1 -> 0.010638267 | V22: 45621 | W22: =SUMPRODUCT(R22:T22,$C$6:$E$6) -> 0.0022327636
L23: 45622 | M23: =Data!B20 -> 244.78809 | N23: =Data!H20 -> 127.70413 | O23: =Data!N20 -> 46.652122 | Q23: 45622 | R23: =(M23/M22)-1 -> -0.0012785929 | S23: =(N23/N22)-1 -> -0.017806358 | T23: =(O23/O22)-1 -> 0.0052631428 | V23: 45622 | W23: =SUMPRODUCT(R23:T23,$C$6:$E$6) -> -0.0059271784
B24: Standard Deviation | C24: {=SQRT(MMULT(MMULT(C6:E6,H17:J19),TRANSPOSE(C6:E6)))} -> 0.01775885 | L24: 45623 | M24: =Data!B21 -> 244.6118 | N24: =Data!H21 -> 127.63606 | O24: =Data!N21 -> 46.671661 | Q24: 45623 | R24: =(M24/M23)-1 -> -0.00072015266 | S24: =(N24/N23)-1 -> -0.00053302471 | T24: =(O24/O23)-1 -> 0.0004188208 | V24: 45623 | W24: =SUMPRODUCT(R24:T24,$C$6:$E$6) -> -0.00030360944
B25: of Portfolio | L25: 45625 | M25: =Data!B22 -> 244.54327 | N25: =Data!H22 -> 128.02515 | O25: =Data!N22 -> 46.417641 | Q25: 45625 | R25: =(M25/M24)-1 -> -0.00028014683 | S25: =(N25/N24)-1 -> 0.003048385 | T25: =(O25/O24)-1 -> -0.005442718 | V25: 45625 | W25: =SUMPRODUCT(R25:T25,$C$6:$E$6) -> -0.00049750544
L26: 45628 | M26: =Data!B23 -> 241.14522 | N26: =Data!H23 -> 127.46094 | O26: =Data!N23 -> 45.958447 | Q26: 45628 | R26: =(M26/M25)-1 -> -0.01389552 | S26: =(N26/N25)-1 -> -0.0044070169 | T26: =(O26/O25)-1 -> -0.0098926653 | V26: 45628 | W26: =SUMPRODUCT(R26:T26,$C$6:$E$6) -> -0.0088992624
L27: 45629 | M27: =Data!B24 -> 239.74486 | N27: =Data!H24 -> 126.88702 | O27: =Data!N24 -> 45.743504 | Q27: 45629 | R27: =(M27/M26)-1 -> -0.0058071237 | S27: =(N27/N26)-1 -> -0.0045027223 | T27: =(O27/O26)-1 -> -0.0046768973 | V27: 45629 | W27: =SUMPRODUCT(R27:T27,$C$6:$E$6) -> -0.0049462952
L28: 45630 | M28: =Data!B25 -> 238.35426 | N28: =Data!H25 -> 126.44928 | O28: =Data!N25 -> 45.303852 | Q28: 45630 | R28: =(M28/M27)-1 -> -0.0058003099 | S28: =(N28/N27)-1 -> -0.0034498133 | T28: =(O28/O27)-1 -> -0.0096112334 | V28: 45630 | W28: =SUMPRODUCT(R28:T28,$C$6:$E$6) -> -0.0060033883
L29: 45631 | M29: =Data!B26 -> 240.39117 | N29: =Data!H26 -> 126.77029 | O29: =Data!N26 -> 45.919369 | Q29: 45631 | R29: =(M29/M28)-1 -> 0.0085457293 | S29: =(N29/N28)-1 -> 0.0025386812 | T29: =(O29/O28)-1 -> 0.013586409 | V29: 45631 | W29: =SUMPRODUCT(R29:T29,$C$6:$E$6) -> 0.0076551139
L30: 45632 | M30: =Data!B27 -> 242.23221 | N30: =Data!H27 -> 126.4201 | O30: =Data!N27 -> 45.929192 | Q30: 45632 | R30: =(M30/M29)-1 -> 0.0076584922 | S30: =(N30/N29)-1 -> -0.0027623917 | T30: =(O30/O29)-1 -> 0.00021391508 | V30: 45632 | W30: =SUMPRODUCT(R30:T30,$C$6:$E$6) -> 0.0012567655
L31: 45635 | M31: =Data!B28 -> 238.75578 | N31: =Data!H28 -> 125.07769 | O31: =Data!N28 -> 45.103943 | Q31: 45635 | R31: =(M31/M30)-1 -> -0.014351622 | S31: =(N31/N30)-1 -> -0.010618682 | T31: =(O31/O30)-1 -> -0.017967848 | V31: 45635 | W31: =SUMPRODUCT(R31:T31,$C$6:$E$6) -> -0.013943314
L32: 45636 | M32: =Data!B29 -> 237.82547 | N32: =Data!H29 -> 123.33644 | O32: =Data!N29 -> 44.946751 | Q32: 45636 | R32: =(M32/M31)-1 -> -0.003896505 | S32: =(N32/N31)-1 -> -0.01392134 | T32: =(O32/O31)-1 -> -0.0034851106 | V32: 45636 | W32: =SUMPRODUCT(R32:T32,$C$6:$E$6) -> -0.0077830208
L33: 45637 | M33: =Data!B30 -> 238.48158 | N33: =Data!H30 -> 124.11465 | O33: =Data!N30 -> 45.270958 | Q33: 45637 | R33: =(M33/M32)-1 -> 0.002758799 | S33: =(N33/N32)-1 -> 0.0063096183 | T33: =(O33/O32)-1 -> 0.0072131422 | V33: 45637 | W33: =SUMPRODUCT(R33:T33,$C$6:$E$6) -> 0.0055154297
L34: 45638 | M34: =Data!B31 -> 236.52306 | N34: =Data!H31 -> 124.42593 | O34: =Data!N31 -> 45.270958 | Q34: 45638 | R34: =(M34/M33)-1 -> -0.0082124858 | S34: =(N34/N33)-1 -> 0.0025079981 | T34: =(O34/O33)-1 -> 0 | V34: 45638 | W34: =SUMPRODUCT(R34:T34,$C$6:$E$6) -> -0.0014605465
L35: 45639 | M35: =Data!B32 -> 234.966 | N35: =Data!H32 -> 123.92982 | O35: =Data!N32 -> 44.868149 | Q35: 45639 | R35: =(M35/M34)-1 -> -0.0065830902 | S35: =(N35/N34)-1 -> -0.0039871223 | T35: =(O35/O34)-1 -> -0.0088977384 | V35: 45639 | W35: =SUMPRODUCT(R35:T35,$C$6:$E$6) -> -0.0062390975
L36: 45642 | M36: =Data!B33 -> 234.61346 | N36: =Data!H33 -> 125.51543 | O36: =Data!N33 -> 44.671665 | Q36: 45642 | R36: =(M36/M35)-1 -> -0.0015003833 | S36: =(N36/N35)-1 -> 0.012794352 | T36: =(O36/O35)-1 -> -0.0043791335 | V36: 45642 | W36: =SUMPRODUCT(R36:T36,$C$6:$E$6) -> 0.0033538858
L37: 45643 | M37: =Data!B34 -> 233.41876 | N37: =Data!H34 -> 124.26057 | O37: =Data!N34 -> 44.259041 | Q37: 45643 | R37: =(M37/M36)-1 -> -0.0050922148 | S37: =(N37/N36)-1 -> -0.0099976549 | T37: =(O37/O36)-1 -> -0.0092368251 | V37: 45643 | W37: =SUMPRODUCT(R37:T37,$C$6:$E$6) -> -0.0082977739
... L254: 45960 | M254: =Data!B251 -> 309.44 | N254: =Data!H251 -> 164.25999 | O254: =Data!N251 -> 53.029999 | Q254: 45960 | R254: =(M254/M253)-1 -> 0.012863712 | S254: =(N254/N253)-1 -> 0.0074985807 | T254: =(O254/O253)-1 -> 0.0085583289 | V254: 45960 | W254: =SUMPRODUCT(R254:T254,$C$6:$E$6) -> 0.0094260444

Sheet Historical Simulation
A2: Historical Data | F2: Returns | V2: Arranging Returns in Ascending Order
A3: Date | B3: JPM | C3: MS | D3: BAC | F3: Date | G3: JPM | H3: MS | I3: BAC | J3: Returns of Portfolio | L3: Assumption | M3: JPM | N3: MS | O3: BAC | V3: Rank | W3: Portfoilo Returns
A4: 45597 | B4: =Data!B3 -> 218.31844 | C4: 113.66718 | D4: 40.799843 | F4: 45597 | L4: Weights | M4: 0.3 | N4: 0.4 | O4: 0.3 | V4: 1 | W4: -0.09212685
A5: 45600 | B5: =Data!B4 -> 215.22394 | C5: 112.97652 | D5: 40.379734 | F5: 45600 | G5: =B5/B4-1 -> -0.014174239 | H5: =C5/C4-1 -> -0.0060761475 | I5: =D5/D4-1 -> -0.010296824 | J5: =SUMPRODUCT(G5:I5,$M$4:$O$4) -> -0.0097717779 | V5: 2 | W5: -0.075281298
A6: 45601 | B6: =Data!B5 -> 216.89848 | C6: 114.60104 | D6: 40.917088 | F6: 45601 | G6: =B6/B5-1 -> 0.0077804788 | H6: =C6/C5-1 -> 0.014379265 | I6: =D6/D5-1 -> 0.013307505 | J6: =SUMPRODUCT(G6:I6,$M$4:$O$4) -> 0.012078101 | V6: 3 | W6: -0.053920453
A7: 45602 | B7: =Data!B6 -> 241.93843 | C7: 127.90842 | D7: 44.365925 | F7: 45602 | G7: =B7/B6-1 -> 0.11544547 | H7: =C7/C6-1 -> 0.11611913 | I7: =D7/D6-1 -> 0.084288435 | J7: =SUMPRODUCT(G7:I7,$M$4:$O$4) -> 0.10636782 | V7: 4 | W7: -0.049317575
A8: 45603 | B8: =Data!B7 -> 231.47981 | C8: 124.94151 | D8: 43.740643 | F8: 45603 | G8: =B8/B7-1 -> -0.043228429 | H8: =C8/C7-1 -> -0.023195591 | I8: =D8/D7-1 -> -0.014093751 | J8: =SUMPRODUCT(G8:I8,$M$4:$O$4) -> -0.02647489 | L8: VaR Using Historical Method | V8: 5 | W8: -0.041358226
A9: 45604 | B9: =Data!B8 -> 232.06737 | C9: 126.00179 | D9: 44.092361 | F9: 45604 | G9: =B9/B8-1 -> 0.0025382556 | H9: =C9/C8-1 -> 0.008486271 | I9: =D9/D8-1 -> 0.0080410091 | J9: =SUMPRODUCT(G9:I9,$M$4:$O$4) -> 0.0065682878 | L9: Total No. of Data | M9: 249 | N9: =M9 -> 249 | O9: =M9 -> 249 | V9: 6 | W9: -0.038088628
A10: 45607 | B10: =Data!B9 -> 234.32947 | C10: 129.88313 | D10: 45.020523 | F10: 45607 | G10: =B10/B9-1 -> 0.0097476015 | H10: =C10/C9-1 -> 0.030803848 | I10: =D10/D9-1 -> 0.021050395 | J10: =SUMPRODUCT(G10:I10,$M$4:$O$4) -> 0.021560938 | L10: CI | M10: 0.99 | N10: 0.95 | O10: 0.9 | V10: 7 | W10: -0.036058368
A11: 45608 | B11: =Data!B10 -> 234.59389 | C11: 128.70609 | D11: 44.80558 | F11: 45608 | G11: =B11/B10-1 -> 0.0011284093 | H11: =C11/C10-1 -> -0.0090623602 | I11: =D11/D10-1 -> -0.0047743322 | J11: =SUMPRODUCT(G11:I11,$M$4:$O$4) -> -0.0047187209 | L11: Alpha | M11: =1-M10 -> 0.01 | N11: =1-N10 -> 0.05 | O11: =1-O10 -> 0.1 | V11: 8 | W11: -0.027942044
A12: 45609 | B12: =Data!B11 -> 236.16072 | C12: 129.14383 | D12: 44.81535 | F12: 45609 | G12: =B12/B11-1 -> 0.0066789187 | H12: =C12/C11-1 -> 0.0034011146 | I12: =D12/D11-1 -> 0.00021804069 | J12: =SUMPRODUCT(G12:I12,$M$4:$O$4) -> 0.0034295336 | L12: Historic VaR is at Position | M12: =M9*M11 -> 2.49 | N12: =N9*N11 -> 12.45 | O12: =O9*O11 -> 24.9 | R12: VaR - Percentile Approach | V12: 9 | W12: -0.026769984
A13: 45610 | B13: =Data!B12 -> 236.856 | C13: 128.8228 | D13: 44.844658 | F13: 45610 | G13: =B13/B12-1 -> 0.0029441051 | H13: =C13/C12-1 -> -0.0024858304 | I13: =D13/D12-1 -> 0.00065397948 | J13: =SUMPRODUCT(G13:I13,$M$4:$O$4) -> 8.5093195e-05 | L13: Historic VaR is at Position (Rounded) | M13: =ROUNDUP(M12,0) -> 3 | N13: =ROUNDUP(N12,0) -> 13 | O13: =ROUNDUP(O12,0) -> 25 | Q13: CI | R13: 0.99 | S13: 0.95 | T13: 0.9 | V13: 10 | W13: -0.026637408
A14: 45611 | B14: =Data!B13 -> 240.22469 | C14: 130.40842 | D14: 45.675114 | F14: 45611 | G14: =B14/B13-1 -> 0.014222493 | H14: =C14/C13-1 -> 0.012308513 | I14: =D14/D13-1 -> 0.0185185 | J14: =SUMPRODUCT(G14:I14,$M$4:$O$4) -> 0.014745703 | L14: Returns at specific position | M14: =W6 -> -0.053920453 | N14: =W16 -> -0.025997085 | O14: =W28 -> -0.014989714 | Q14: Returns at specific position | R14: =_xlfn.PERCENTILE.EXC(W4:W254,0.01) -> -0.064814484 | S14: =_xlfn.PERCENTILE.EXC(W4:W254,0.05) -> -0.026007127 | T14: =_xlfn.PERCENTILE.EXC(W4:W254,0.1) -> -0.01499007 | V14: 11 | W14: -0.02647489
A15: 45614 | B15: =Data!B14 -> 239.95049 | C15: 130.13605 | D15: 45.645809 | F15: 45614 | G15: =B15/B14-1 -> -0.0011414332 | H15: =C15/C14-1 -> -0.0020885875 | I15: =D15/D14-1 -> -0.0006415858 | J15: =SUMPRODUCT(G15:I15,$M$4:$O$4) -> -0.0013703407 | L15: Portfolio Value | M15: =1*10^6 -> 1000000 | N15: =1*10^6 -> 1000000 | O15: =1*10^6 -> 1000000 | Q15: Portfolio Value | R15: =1*10^6 -> 1000000 | S15: =1*10^6 -> 1000000 | T15: =1*10^6 -> 1000000 | V15: 12 | W15: -0.026015343
A16: 45615 | B16: =Data!B15 -> 238.0507 | C16: 128.63802 | D16: 45.342934 | F16: 45615 | G16: =B16/B15-1 -> -0.0079173846 | H16: =C16/C15-1 -> -0.011511273 | I16: =D16/D15-1 -> -0.0066353412 | J16: =SUMPRODUCT(G16:I16,$M$4:$O$4) -> -0.0089703271 | L16: 1 Day VaR | M16: =M15*M14 -> -53920.453 | N16: =N15*N14 -> -25997.085 | O16: =O15*O14 -> -14989.714 | R16: =R15*R14 -> -64814.484 | S16: =S15*S14 -> -26007.127 | T16: =T15*T14 -> -14990.07 | V16: 13 | W16: -0.025997085
A17: 45616 | B17: =Data!B16 -> 235.78859 | C17: 128.103 | D17: 45.000984 | F17: 45616 | G17: =B17/B16-1 -> -0.0095026624 | H17: =C17/C16-1 -> -0.0041591043 | I17: =D17/D16-1 -> -0.0075414058 | J17: =SUMPRODUCT(G17:I17,$M$4:$O$4) -> -0.0067768622 | L17: Expected Shortfall | M17: =AVERAGE(W4:W5)*M15 -> -83704.074 | N17: =AVERAGE(W4:W15)*N15 -> -43332.589 | O17: =AVERAGE(W4:W27)*O15 -> -31732.783 | V17: 14 | W17: -0.02496024
A18: 45617 | B18: =Data!B17 -> 239.6861 | C18: 131.3131 | D18: 45.391781 | F18: 45617 | G18: =B18/B17-1 -> 0.016529666 | H18: =C18/C17-1 -> 0.025058729 | I18: =D18/D17-1 -> 0.0086841803 | J18: =SUMPRODUCT(G18:I18,$M$4:$O$4) -> 0.017587646 | L18: 10 Day VaR | M18: =M16*SQRT(10) -> -170511.45 | N18: =N16*SQRT(10) -> -82210.001 | O18: =O16*SQRT(10) -> -47401.638 | V18: 15 | W18: -0.024043288
A19: 45618 | B19: =Data!B18 -> 243.39754 | C19: 131.02126 | D19: 45.919369 | F19: 45618 | G19: =B19/B18-1 -> 0.01548459 | H19: =C19/C18-1 -> -0.0022224714 | I19: =D19/D18-1 -> 0.011622983 | J19: =SUMPRODUCT(G19:I19,$M$4:$O$4) -> 0.0072432834 | V19: 16 | W19: -0.022713005
A20: 45621 | B20: =Data!B19 -> 245.10147 | C20: 130.0193 | D20: 46.407871 | F20: 45621 | G20: =B20/B19-1 -> 0.0070006202 | H20: =C20/C19-1 -> -0.0076472563 | I20: =D20/D19-1 -> 0.010638267 | J20: =SUMPRODUCT(G20:I20,$M$4:$O$4) -> 0.0022327636 | V20: 17 | W20: -0.020042386
A21: 45622 | B21: =Data!B20 -> 244.78809 | C21: 127.70413 | D21: 46.652122 | F21: 45622 | G21: =B21/B20-1 -> -0.0012785929 | H21: =C21/C20-1 -> -0.017806358 | I21: =D21/D20-1 -> 0.0052631428 | J21: =SUMPRODUCT(G21:I21,$M$4:$O$4) -> -0.0059271784 | V21: 18 | W21: -0.019201954
A22: 45623 | B22: =Data!B21 -> 244.6118 | C22: 127.63606 | D22: 46.671661 | F22: 45623 | G22: =B22/B21-1 -> -0.00072015266 | H22: =C22/C21-1 -> -0.00053302471 | I22: =D22/D21-1 -> 0.0004188208 | J22: =SUMPRODUCT(G22:I22,$M$4:$O$4) -> -0.00030360944 | V22: 19 | W22: -0.019086006
A23: 45625 | B23: =Data!B22 -> 244.54327 | C23: 128.02515 | D23: 46.417641 | F23: 45625 | G23: =B23/B22-1 -> -0.00028014683 | H23: =C23/C22-1 -> 0.003048385 | I23: =D23/D22-1 -> -0.005442718 | J23: =SUMPRODUCT(G23:I23,$M$4:$O$4) -> -0.00049750544 | V23: 20 | W23: -0.019035087
A24: 45628 | B24: =Data!B23 -> 241.14522 | C24: 127.46094 | D24: 45.958447 | F24: 45628 | G24: =B24/B23-1 -> -0.01389552 | H24: =C24/C23-1 -> -0.0044070169 | I24: =D24/D23-1 -> -0.0098926653 | J24: =SUMPRODUCT(G24:I24,$M$4:$O$4) -> -0.0088992624 | V24: 21 | W24: -0.018321996
A25: 45629 | B25: =Data!B24 -> 239.74486 | C25: 126.88702 | D25: 45.743504 | F25: 45629 | G25: =B25/B24-1 -> -0.0058071237 | H25: =C25/C24-1 -> -0.0045027223 | I25: =D25/D24-1 -> -0.0046768973 | J25: =SUMPRODUCT(G25:I25,$M$4:$O$4) -> -0.0049462952 | V25: 22 | W25: -0.017427528
A26: 45630 | B26: =Data!B25 -> 238.35426 | C26: 126.44928 | D26: 45.303852 | F26: 45630 | G26: =B26/B25-1 -> -0.0058003099 | H26: =C26/C25-1 -> -0.0034498133 | I26: =D26/D25-1 -> -0.0096112334 | J26: =SUMPRODUCT(G26:I26,$M$4:$O$4) -> -0.0060033883 | V26: 23 | W26: -0.015773885
A27: 45631 | B27: =Data!B26 -> 240.39117 | C27: 126.77029 | D27: 45.919369 | F27: 45631 | G27: =B27/B26-1 -> 0.0085457293 | H27: =C27/C26-1 -> 0.0025386812 | I27: =D27/D26-1 -> 0.013586409 | J27: =SUMPRODUCT(G27:I27,$M$4:$O$4) -> 0.0076551139 | V27: 24 | W27: -0.014993273
A28: 45632 | B28: =Data!B27 -> 242.23221 | C28: 126.4201 | D28: 45.929192 | F28: 45632 | G28: =B28/B27-1 -> 0.0076584922 | H28: =C28/C27-1 -> -0.0027623917 | I28: =D28/D27-1 -> 0.00021391508 | J28: =SUMPRODUCT(G28:I28,$M$4:$O$4) -> 0.0012567655 | V28: 25 | W28: -0.014989714
A29: 45635 | B29: =Data!B28 -> 238.75578 | C29: 125.07769 | D29: 45.103943 | F29: 45635 | G29: =B29/B28-1 -> -0.014351622 | H29: =C29/C28-1 -> -0.010618682 | I29: =D29/D28-1 -> -0.017967848 | J29: =SUMPRODUCT(G29:I29,$M$4:$O$4) -> -0.013943314 | V29: 26 | W29: -0.014710249
A30: 45636 | B30: =Data!B29 -> 237.82547 | C30: 123.33644 | D30: 44.946751 | F30: 45636 | G30: =B30/B29-1 -> -0.003896505 | H30: =C30/C29-1 -> -0.01392134 | I30: =D30/D29-1 -> -0.0034851106 | J30: =SUMPRODUCT(G30:I30,$M$4:$O$4) -> -0.0077830208 | V30: 27 | W30: -0.014610979
... A251: 45959 | B251: =Data!B250 -> 305.51001 | C251: 163.03745 | D251: 52.580002 | F251: 45959 | G251: =B251/B250-1 -> 0.00049130345 | H251: =C251/C250-1 -> -0.0071424675 | I251: =D251/D250-1 -> -0.0054850975 | J251: =SUMPRODUCT(G251:I251,$M$4:$O$4) -> -0.0043551252 | V251: 248 | W251: 0.10636782
A252: 45960 | B252: =Data!B251 -> 309.44 | C252: 164.25999 | D252: 53.029999 | F252: 45960 | G252: =B252/B251-1 -> 0.012863712 | H252: =C252/C251-1 -> 0.0074985807 | I252: =D252/D251-1 -> 0.0085583289 | J252: =SUMPRODUCT(G252:I252,$M$4:$O$4) -> 0.0094260444

Sheet Monte Carlo Simulation
AG1: (As on 30/10/2023)
AC2: S1 | AD2: S2 | AE2: S3 | AG2: S0 | AH2: =B254 -> 309.44 | AI2: =C254 -> 164.25999 | AJ2: =D254 -> 53.029999
AC3: Wiener Process or Brownian Motion
A4: Historical Price | F4: Returns | P4: Assumption on Weights of the Stocks | W4: Uncorrelated Random Variable | AC4: Correlated Random Variable | AG4: Simulate Stock Price | AM4: Return
A5: Date | B5: JPM | C5: MS | D5: BAC | F5: Date | G5: JPM | H5: MS | I5: BAC | K5: VaR Using Monte Carlo Simulation Method | P5: JPM | Q5: MS | R5: BAC | T5: Arranging Returns in Ascending Order | W5: Sims | X5: W1 | Y5: W2 | Z5: W3 | AB5: Sims | AC5: W1 | AD5: W2 | AE5: W3 | AG5: Simulation | AH5: JPM | AI5: MS | AJ5: BAC | AM5: JPM | AN5: MS | AO5: BAC | AP5: Portfolio R
A6: 45597 | B6: =Data!B3 -> 218.31844 | C6: =Data!H3 -> 113.66718 | D6: =Data!N3 -> 40.799843 | F6: 45597 | K6: Total No. of Returns | L6: 1000 | M6: =L6 -> 1000 | N6: =L6 -> 1000 | P6: 0.3 | Q6: 0.4 | R6: 0.3 | T6: Rank | U6: Portfolio Return | W6: 1 | X6: =_xlfn.NORM.S.INV(RAND()) -> 0.24002695 | Y6: =_xlfn.NORM.S.INV(RAND()) -> 0.48420223 | Z6: =_xlfn.NORM.S.INV(RAND()) -> -0.91605532 | AB6: 1 | AC6: =SUMPRODUCT($Q$24:$S$24,X6:Z6) -> 0.24002695 | AD6: =SUMPRODUCT($Q$25:$S$25,X6:Z6) -> 0.44745153 | AE6: =SUMPRODUCT($Q$26:$S$26,X6:Z6) -> -0.13533344 | AG6: 1 | AH6: =$L$21*EXP(($L$19-(($L$20^2)/2))*(1/252)+$L$20*AC6) -> 310.70731 | AI6: =$M$21*EXP(($M$19-(($M$20^2)/2))*(1/252)+$M$20*AD6) -> 165.79624 | AJ6: =$N$21*EXP(($N$19-(($N$20^2)/2))*(1/252)+$N$20*AE6) -> 52.903009 | AL6: 1 | AM6: =AH6/$AH$2-1 -> 0.0040954946 | AN6: =AI6/$AI$2-1 -> 0.0093525441 | AO6: =AJ6/$AJ$2-1 -> -0.002394684 | AP6: =SUMPRODUCT($P$6:$R$6,AM6:AO6) -> 0.0042512608
A7: 45600 | B7: =Data!B4 -> 215.22394 | C7: =Data!H4 -> 112.97652 | D7: =Data!N4 -> 40.379734 | F7: 45600 | G7: =B7/B6-1 -> -0.014174239 | H7: =C7/C6-1 -> -0.0060761475 | I7: =D7/D6-1 -> -0.010296824 | K7: CI | L7: 0.99 | M7: 0.95 | N7: 0.9 | T7: 1 | U7: -0.052240691 | W7: 2 | X7: =_xlfn.NORM.S.INV(RAND()) -> 1.1358008 | Y7: =_xlfn.NORM.S.INV(RAND()) -> 0.90008217 | Z7: =_xlfn.NORM.S.INV(RAND()) -> -0.81544719 | AB7: 2 | AC7: =SUMPRODUCT($Q$24:$S$24,X7:Z7) -> 1.1358008 | AD7: =SUMPRODUCT($Q$25:$S$25,X7:Z7) -> 1.4318537 | AE7: =SUMPRODUCT($Q$26:$S$26,X7:Z7) -> 0.76168366 | AG7: 2 | AH7: =$L$21*EXP(($L$19-(($L$20^2)/2))*(1/252)+$L$20*AC7) -> 315.47631 | AI7: =$M$21*EXP(($M$19-(($M$20^2)/2))*(1/252)+$M$20*AD7) -> 169.22459 | AJ7: =$N$21*EXP(($N$19-(($N$20^2)/2))*(1/252)+$N$20*AE7) -> 53.751928 | AL7: 2 | AM7: =AH7/$AH$2-1 -> 0.019507195 | AN7: =AI7/$AI$2-1 -> 0.030224032 | AO7: =AJ7/$AJ$2-1 -> 0.013613607 | AP7: =SUMPRODUCT($P$6:$R$6,AM7:AO7) -> 0.022025853
A8: 45601 | B8: =Data!B5 -> 216.89848 | C8: =Data!H5 -> 114.60104 | D8: =Data!N5 -> 40.917088 | F8: 45601 | G8: =B8/B7-1 -> 0.0077804788 | H8: =C8/C7-1 -> 0.014379265 | I8: =D8/D7-1 -> 0.013307505 | K8: Alpha | L8: =100%-L7 -> 0.01 | M8: =100%-M7 -> 0.05 | N8: =100%-N7 -> 0.1 | T8: 2 | U8: -0.051621956 | W8: 3 | X8: =_xlfn.NORM.S.INV(RAND()) -> 0.54522074 | Y8: =_xlfn.NORM.S.INV(RAND()) -> 1.7647349 | Z8: =_xlfn.NORM.S.INV(RAND()) -> 1.3807243 | AB8: 3 | AC8: =SUMPRODUCT($Q$24:$S$24,X8:Z8) -> 0.54522074 | AD8: =SUMPRODUCT($Q$25:$S$25,X8:Z8) -> 1.3439933 | AE8: =SUMPRODUCT($Q$26:$S$26,X8:Z8) -> 1.6329119 | AG8: 3 | AH8: =$L$21*EXP(($L$19-(($L$20^2)/2))*(1/252)+$L$20*AC8) -> 312.32398 | AI8: =$M$21*EXP(($M$19-(($M$20^2)/2))*(1/252)+$M$20*AD8) -> 168.91575 | AJ8: =$N$21*EXP(($N$19-(($N$20^2)/2))*(1/252)+$N$20*AE8) -> 54.589481 | AL8: 3 | AM8: =AH8/$AH$2-1 -> 0.0093199792 | AN8: =AI8/$AI$2-1 -> 0.028343789 | AO8: =AJ8/$AJ$2-1 -> 0.029407539 | AP8: =SUMPRODUCT($P$6:$R$6,AM8:AO8) -> 0.022955771
A9: 45602 | B9: =Data!B6 -> 241.93843 | C9: =Data!H6 -> 127.90842 | D9: =Data!N6 -> 44.365925 | F9: 45602 | G9: =B9/B8-1 -> 0.11544547 | H9: =C9/C8-1 -> 0.11611913 | I9: =D9/D8-1 -> 0.084288435 | K9: VaR is at Position | L9: =L6*L8 -> 10 | M9: =M6*M8 -> 50 | N9: =N6*N8 -> 100 | T9: 3 | U9: -0.051251505 | W9: 4 | X9: =_xlfn.NORM.S.INV(RAND()) -> 0.99645649 | Y9: =_xlfn.NORM.S.INV(RAND()) -> -0.13904651 | Z9: =_xlfn.NORM.S.INV(RAND()) -> -0.44127684 | AB9: 4 | AC9: =SUMPRODUCT($Q$24:$S$24,X9:Z9) -> 0.99645649 | AD9: =SUMPRODUCT($Q$25:$S$25,X9:Z9) -> 0.79857956 | AE9: =SUMPRODUCT($Q$26:$S$26,X9:Z9) -> 0.5509964 | AG9: 4 | AH9: =$L$21*EXP(($L$19-(($L$20^2)/2))*(1/252)+$L$20*AC9) -> 314.72968 | AI9: =$M$21*EXP(($M$19-(($M$20^2)/2))*(1/252)+$M$20*AD9) -> 167.01106 | AJ9: =$N$21*EXP(($N$19-(($N$20^2)/2))*(1/252)+$N$20*AE9) -> 53.551322 | AL9: 4 | AM9: =AH9/$AH$2-1 -> 0.017094345 | AN9: =AI9/$AI$2-1 -> 0.016748267 | AO9: =AJ9/$AJ$2-1 -> 0.0098307226 | AP9: =SUMPRODUCT($P$6:$R$6,AM9:AO9) -> 0.014776827
A10: 45603 | B10: =Data!B7 -> 231.47981 | C10: =Data!H7 -> 124.94151 | D10: =Data!N7 -> 43.740643 | F10: 45603 | G10: =B10/B9-1 -> -0.043228429 | H10: =C10/C9-1 -> -0.023195591 | I10: =D10/D9-1 -> -0.014093751 | K10: VaR is at Position (Rounded) | L10: =ROUNDUP(L9,0) -> 10 | M10: =ROUNDUP(M9,0) -> 50 | N10: =ROUNDUP(N9,0) -> 100 | T10: 4 | U10: -0.046288246 | W10: 5 | X10: =_xlfn.NORM.S.INV(RAND()) -> -0.1540573 | Y10: =_xlfn.NORM.S.INV(RAND()) -> 0.035855151 | Z10: =_xlfn.NORM.S.INV(RAND()) -> 0.87057785 | AB10: 5 | AC10: =SUMPRODUCT($Q$24:$S$24,X10:Z10) -> -0.1540573 | AD10: =SUMPRODUCT($Q$25:$S$25,X10:Z10) -> -0.11638983 | AE10: =SUMPRODUCT($Q$26:$S$26,X10:Z10) -> 0.32598374 | AG10: 5 | AH10: =$L$21*EXP(($L$19-(($L$20^2)/2))*(1/252)+$L$20*AC10) -> 308.63215 | AI10: =$M$21*EXP(($M$19-(($M$20^2)/2))*(1/252)+$M$20*AD10) -> 163.86394 | AJ10: =$N$21*EXP(($N$19-(($N$20^2)/2))*(1/252)+$N$20*AE10) -> 53.337902 | AL10: 5 | AM10: =AH10/$AH$2-1 -> -0.0026106837 | AN10: =AI10/$AI$2-1 -> -0.0024111212 | AO10: =AJ10/$AJ$2-1 -> 0.0058062149 | AP10: =SUMPRODUCT($P$6:$R$6,AM10:AO10) -> -5.7891057e-06
A11: 45604 | B11: =Data!B8 -> 232.06737 | C11: =Data!H8 -> 126.00179 | D11: =Data!N8 -> 44.092361 | F11: 45604 | G11: =B11/B10-1 -> 0.0025382556 | H11: =C11/C10-1 -> 0.008486271 | I11: =D11/D10-1 -> 0.0080410091 | K11: Returns at specific position | L11: =VLOOKUP(L10,T6:U1005,2,FALSE) -> -0.038068767 | M11: =VLOOKUP(M10,T6:U1005,2,FALSE) -> -0.029734167 | N11: =VLOOKUP(N10,T6:U1005,2,FALSE) -> -0.023804262 | P11: Percentile Approach | T11: 5 | U11: -0.043973661 | W11: 6 | X11: =_xlfn.NORM.S.INV(RAND()) -> -0.60714798 | Y11: =_xlfn.NORM.S.INV(RAND()) -> 0.038844409 | Z11: =_xlfn.NORM.S.INV(RAND()) -> 0.50639309 | AB11: 6 | AC11: =SUMPRODUCT($Q$24:$S$24,X11:Z11) -> -0.60714798 | AD11: =SUMPRODUCT($Q$25:$S$25,X11:Z11) -> -0.50918588 | AE11: =SUMPRODUCT($Q$26:$S$26,X11:Z11) -> -0.22784528 | AG11: 6 | AH11: =$L$21*EXP(($L$19-(($L$20^2)/2))*(1/252)+$L$20*AC11) -> 306.2634 | AI11: =$M$21*EXP(($M$19-(($M$20^2)/2))*(1/252)+$M$20*AD11) -> 162.53115 | AJ11: =$N$21*EXP(($N$19-(($N$20^2)/2))*(1/252)+$N$20*AE11) -> 52.816224 | AL11: 6 | AM11: =AH11/$AH$2-1 -> -0.010265649 | AN11: =AI11/$AI$2-1 -> -0.010525075 | AO11: =AJ11/$AJ$2-1 -> -0.0040312129 | AP11: =SUMPRODUCT($P$6:$R$6,AM11:AO11) -> -0.0084990884
A12: 45607 | B12: =Data!B9 -> 234.32947 | C12: =Data!H9 -> 129.88313 | D12: =Data!N9 -> 45.020523 | F12: 45607 | G12: =B12/B11-1 -> 0.0097476015 | H12: =C12/C11-1 -> 0.030803848 | I12: =D12/D11-1 -> 0.021050395 | K12: Portfolio Value | L12: =1*10^6 -> 1000000 | M12: =1*10^6 -> 1000000 | N12: =1*10^6 -> 1000000 | P12: 0.99 | Q12: 0.95 | R12: 0.9 | T12: 6 | U12: -0.042143272 | W12: 7 | X12: =_xlfn.NORM.S.INV(RAND()) -> -1.2405465 | Y12: =_xlfn.NORM.S.INV(RAND()) -> 0.57718025 | Z12: =_xlfn.NORM.S.INV(RAND()) -> -0.29727311 | AB12: 7 | AC12: =SUMPRODUCT($Q$24:$S$24,X12:Z12) -> -1.2405465 | AD12: =SUMPRODUCT($Q$25:$S$25,X12:Z12) -> -0.79509515 | AE12: =SUMPRODUCT($Q$26:$S$26,X12:Z12) -> -1.0041094 | AG12: 7 | AH12: =$L$21*EXP(($L$19-(($L$20^2)/2))*(1/252)+$L$20*AC12) -> 302.98244 | AI12: =$M$21*EXP(($M$19-(($M$20^2)/2))*(1/252)+$M$20*AD12) -> 161.56785 | AJ12: =$N$21*EXP(($N$19-(($N$20^2)/2))*(1/252)+$N$20*AE12) -> 52.093599 | AL12: 7 | AM12: =AH12/$AH$2-1 -> -0.02086854 | AN12: =AI12/$AI$2-1 -> -0.016389546 | AO12: =AJ12/$AJ$2-1 -> -0.017657932 | AP12: =SUMPRODUCT($P$6:$R$6,AM12:AO12) -> -0.01811376
A13: 45608 | B13: =Data!B10 -> 234.59389 | C13: =Data!H10 -> 128.70609 | D13: =Data!N10 -> 44.80558 | F13: 45608 | G13: =B13/B12-1 -> 0.0011284093 | H13: =C13/C12-1 -> -0.0090623602 | I13: =D13/D12-1 -> -0.0047743322 | K13: 1 Day VaR | L13: =L12*L11 -> -38068.767 | M13: =M12*M11 -> -29734.167 | N13: =N12*N11 -> -23804.262 | P13: =_xlfn.PERCENTILE.EXC(U7:U1006,0.01) -> -0.038053321 | Q13: =_xlfn.PERCENTILE.EXC(U7:U1006,0.05) -> -0.029724765 | R13: =_xlfn.PERCENTILE.EXC(U7:U1006,0.1) -> -0.023802704 | T13: 7 | U13: -0.040496603 | W13: 8 | X13: =_xlfn.NORM.S.INV(RAND()) -> -0.27425315 | Y13: =_xlfn.NORM.S.INV(RAND()) -> -1.2751515 | Z13: =_xlfn.NORM.S.INV(RAND()) -> 0.14744757 | AB13: 8 | AC13: =SUMPRODUCT($Q$24:$S$24,X13:Z13) -> -0.27425315 | AD13: =SUMPRODUCT($Q$25:$S$25,X13:Z13) -> -0.86696644 | AE13: =SUMPRODUCT($Q$26:$S$26,X13:Z13) -> -0.5010221 | AG13: 8 | AH13: =$L$21*EXP(($L$19-(($L$20^2)/2))*(1/252)+$L$20*AC13) -> 308.00199 | AI13: =$M$21*EXP(($M$19-(($M$20^2)/2))*(1/252)+$M$20*AD13) -> 161.3266 | AJ13: =$N$21*EXP(($N$19-(($N$20^2)/2))*(1/252)+$N$20*AE13) -> 52.560787 | AL13: 8 | AM13: =AH13/$AH$2-1 -> -0.0046471432 | AN13: =AI13/$AI$2-1 -> -0.01785827 | AO13: =AJ13/$AJ$2-1 -> -0.0088480432 | AP13: =SUMPRODUCT($P$6:$R$6,AM13:AO13) -> -0.011191864
A14: 45609 | B14: =Data!B11 -> 236.16072 | C14: =Data!H11 -> 129.14383 | D14: =Data!N11 -> 44.81535 | F14: 45609 | G14: =B14/B13-1 -> 0.0066789187 | H14: =C14/C13-1 -> 0.0034011146 | I14: =D14/D13-1 -> 0.00021804069 | K14: Expected Shortfall | L14: =AVERAGE(U7:U15)*L12 -> -45314.428 | M14: =AVERAGE(U7:U55)*M12 -> -35152.795 | N14: =AVERAGE(U7:U105)*N12 -> -30929.008 | P14: =1*10^6 -> 1000000 | Q14: =1*10^6 -> 1000000 | R14: =1*10^6 -> 1000000 | T14: 8 | U14: -0.040074735 | W14: 9 | X14: =_xlfn.NORM.S.INV(RAND()) -> -0.1597984 | Y14: =_xlfn.NORM.S.INV(RAND()) -> -0.38133694 | Z14: =_xlfn.NORM.S.INV(RAND()) -> -0.68941921 | AB14: 9 | AC14: =SUMPRODUCT($Q$24:$S$24,X14:Z14) -> -0.1597984 | AD14: =SUMPRODUCT($Q$25:$S$25,X14:Z14) -> -0.3269527 | AE14: =SUMPRODUCT($Q$26:$S$26,X14:Z14) -> -0.58558945 | AG14: 9 | AH14: =$L$21*EXP(($L$19-(($L$20^2)/2))*(1/252)+$L$20*AC14) -> 308.60202 | AI14: =$M$21*EXP(($M$19-(($M$20^2)/2))*(1/252)+$M$20*AD14) -> 163.14813 | AJ14: =$N$21*EXP(($N$19-(($N$20^2)/2))*(1/252)+$N$20*AE14) -> 52.481962 | AL14: 9 | AM14: =AH14/$AH$2-1 -> -0.002708049 | AN14: =AI14/$AI$2-1 -> -0.0067689391 | AO14: =AJ14/$AJ$2-1 -> -0.010334462 | AP14: =SUMPRODUCT($P$6:$R$6,AM14:AO14) -> -0.0066203289
A15: 45610 | B15: =Data!B12 -> 236.856 | C15: =Data!H12 -> 128.8228 | D15: =Data!N12 -> 44.844658 | F15: 45610 | G15: =B15/B14-1 -> 0.0029441051 | H15: =C15/C14-1 -> -0.0024858304 | I15: =D15/D14-1 -> 0.00065397948 | K15: 10 Day VaR | L15: =L13*SQRT(10) -> -120384.01 | M15: =M13*SQRT(10) -> -94027.693 | N15: =N13*SQRT(10) -> -75275.687 | P15: =P14*P13 -> -38053.321 | Q15: =Q14*Q13 -> -29724.765 | R15: =R14*R13 -> -23802.704 | T15: 9 | U15: -0.039739181 | W15: 10 | X15: =_xlfn.NORM.S.INV(RAND()) -> 0.10271274 | Y15: =_xlfn.NORM.S.INV(RAND()) -> -1.4080126 | Z15: =_xlfn.NORM.S.INV(RAND()) -> -0.045007121 | AB15: 10 | AC15: =SUMPRODUCT($Q$24:$S$24,X15:Z15) -> 0.10271274 | AD15: =SUMPRODUCT($Q$25:$S$25,X15:Z15) -> -0.60440546 | AE15: =SUMPRODUCT($Q$26:$S$26,X15:Z15) -> -0.32768204 | AG15: 10 | AH15: =$L$21*EXP(($L$19-(($L$20^2)/2))*(1/252)+$L$20*AC15) -> 309.98267 | AI15: =$M$21*EXP(($M$19-(($M$20^2)/2))*(1/252)+$M$20*AD15) -> 162.20969 | AJ15: =$N$21*EXP(($N$19-(($N$20^2)/2))*(1/252)+$N$20*AE15) -> 52.722727 | AL15: 10 | AM15: =AH15/$AH$2-1 -> 0.0017536993 | AN15: =AI15/$AI$2-1 -> -0.012482059 | AO15: =AJ15/$AJ$2-1 -> -0.0057943075 | AP15: =SUMPRODUCT($P$6:$R$6,AM15:AO15) -> -0.0062050059
A16: 45611 | B16: =Data!B13 -> 240.22469 | C16: =Data!H13 -> 130.40842 | D16: =Data!N13 -> 45.675114 | F16: 45611 | G16: =B16/B15-1 -> 0.014222493 | H16: =C16/C15-1 -> 0.012308513 | I16: =D16/D15-1 -> 0.0185185 | T16: 10 | U16: -0.038068767 | W16: 11 | X16: =_xlfn.NORM.S.INV(RAND()) -> -0.89857156 | Y16: =_xlfn.NORM.S.INV(RAND()) -> -0.031299477 | Z16: =_xlfn.NORM.S.INV(RAND()) -> -0.45850692 | AB16: 11 | AC16: =SUMPRODUCT($Q$24:$S$24,X16:Z16) -> -0.89857156 | AD16: =SUMPRODUCT($Q$25:$S$25,X16:Z16) -> -0.79733859 | AE16: =SUMPRODUCT($Q$26:$S$26,X16:Z16) -> -0.97477773 | AG16: 11 | AH16: =$L$21*EXP(($L$19-(($L$20^2)/2))*(1/252)+$L$20*AC16) -> 304.74946 | AI16: =$M$21*EXP(($M$19-(($M$20^2)/2))*(1/252)+$M$20*AD16) -> 161.56031 | AJ16: =$N$21*EXP(($N$19-(($N$20^2)/2))*(1/252)+$N$20*AE16) -> 52.120723 | AL16: 11 | AM16: =AH16/$AH$2-1 -> -0.015158174 | AN16: =AI16/$AI$2-1 -> -0.016435425 | AO16: =AJ16/$AJ$2-1 -> -0.017146441 | AP16: =SUMPRODUCT($P$6:$R$6,AM16:AO16) -> -0.016265554
A17: 45614 | B17: =Data!B14 -> 239.95049 | C17: =Data!H14 -> 130.13605 | D17: =Data!N14 -> 45.645809 | F17: 45614 | G17: =B17/B16-1 -> -0.0011414332 | H17: =C17/C16-1 -> -0.0020885875 | I17: =D17/D16-1 -> -0.0006415858 | T17: 11 | U17: -0.036524156 | W17: 12 | X17: =_xlfn.NORM.S.INV(RAND()) -> 2.1355043 | Y17: =_xlfn.NORM.S.INV(RAND()) -> 0.39312397 | Z17: =_xlfn.NORM.S.INV(RAND()) -> -1.6643829 | AB17: 12 | AC17: =SUMPRODUCT($Q$24:$S$24,X17:Z17) -> 2.1355043 | AD17: =SUMPRODUCT($Q$25:$S$25,X17:Z17) -> 2.051974 | AE17: =SUMPRODUCT($Q$26:$S$26,X17:Z17) -> 1.0068764 | AG17: 12 | AH17: =$L$21*EXP(($L$19-(($L$20^2)/2))*(1/252)+$L$20*AC17) -> 320.8851 | AI17: =$M$21*EXP(($M$19-(($M$20^2)/2))*(1/252)+$M$20*AD17) -> 171.42057 | AJ17: =$N$21*EXP(($N$19-(($N$20^2)/2))*(1/252)+$N$20*AE17) -> 53.986336 | AL17: 12 | AM17: =AH17/$AH$2-1 -> 0.036986472 | AN17: =AI17/$AI$2-1 -> 0.043592953 | AO17: =AJ17/$AJ$2-1 -> 0.018033883 | AP17: =SUMPRODUCT($P$6:$R$6,AM17:AO17) -> 0.033943288
A18: 45615 | B18: =Data!B15 -> 238.0507 | C18: =Data!H15 -> 128.63802 | D18: =Data!N15 -> 45.342934 | F18: 45615 | G18: =B18/B17-1 -> -0.0079173846 | H18: =C18/C17-1 -> -0.011511273 | I18: =D18/D17-1 -> -0.0066353412 | L18: JPM | M18: MS | N18: BAC | T18: 12 | U18: -0.036407533 | W18: 13 | X18: =_xlfn.NORM.S.INV(RAND()) -> -1.1109815 | Y18: =_xlfn.NORM.S.INV(RAND()) -> -0.82502414 | Z18: =_xlfn.NORM.S.INV(RAND()) -> 0.545398 | AB18: 13 | AC18: =SUMPRODUCT($Q$24:$S$24,X18:Z18) -> -1.1109815 | AD18: =SUMPRODUCT($Q$25:$S$25,X18:Z18) -> -1.3732724 | AE18: =SUMPRODUCT($Q$26:$S$26,X18:Z18) -> -0.85776014 | AG18: 13 | AH18: =$L$21*EXP(($L$19-(($L$20^2)/2))*(1/252)+$L$20*AC18) -> 303.65071 | AI18: =$M$21*EXP(($M$19-(($M$20^2)/2))*(1/252)+$M$20*AD18) -> 159.63724 | AJ18: =$N$21*EXP(($N$19-(($N$20^2)/2))*(1/252)+$N$20*AE18) -> 52.229075 | AL18: 13 | AM18: =AH18/$AH$2-1 -> -0.018708944 | AN18: =AI18/$AI$2-1 -> -0.028142916 | AO18: =AJ18/$AJ$2-1 -> -0.015103222 | AP18: =SUMPRODUCT($P$6:$R$6,AM18:AO18) -> -0.021400816
A19: 45616 | B19: =Data!B16 -> 235.78859 | C19: =Data!H16 -> 128.103 | D19: =Data!N16 -> 45.000984 | F19: 45616 | G19: =B19/B18-1 -> -0.0095026624 | H19: =C19/C18-1 -> -0.0041591043 | I19: =D19/D18-1 -> -0.0075414058 | K19: Drift (Average Return) | L19: =AVERAGE(G7:G254) -> 0.0015504217 | M19: =AVERAGE(H7:H254) -> 0.0016997955 | N19: =AVERAGE(I7:I254) -> 0.0012163593 | T19: 13 | U19: -0.036019372 | W19: 14 | X19: =_xlfn.NORM.S.INV(RAND()) -> -2.1687866 | Y19: =_xlfn.NORM.S.INV(RAND()) -> -0.23404162 | Z19: =_xlfn.NORM.S.INV(RAND()) -> 1.146078 | AB19: 14 | AC19: =SUMPRODUCT($Q$24:$S$24,X19:Z19) -> -2.1687866 | AD19: =SUMPRODUCT($Q$25:$S$25,X19:Z19) -> -2.0025493 | AE19: =SUMPRODUCT($Q$26:$S$26,X19:Z19) -> -1.2531759 | AG19: 14 | AH19: =$L$21*EXP(($L$19-(($L$20^2)/2))*(1/252)+$L$20*AC19) -> 298.23762 | AI19: =$M$21*EXP(($M$19-(($M$20^2)/2))*(1/252)+$M$20*AD19) -> 157.56221 | AJ19: =$N$21*EXP(($N$19-(($N$20^2)/2))*(1/252)+$N$20*AE19) -> 51.863844 | AL19: 14 | AM19: =AH19/$AH$2-1 -> -0.036202124 | AN19: =AI19/$AI$2-1 -> -0.040775501 | AO19: =AJ19/$AJ$2-1 -> -0.021990473 | AP19: =SUMPRODUCT($P$6:$R$6,AM19:AO19) -> -0.033767979
A20: 45617 | B20: =Data!B17 -> 239.6861 | C20: =Data!H17 -> 131.3131 | D20: =Data!N17 -> 45.391781 | F20: 45617 | G20: =B20/B19-1 -> 0.016529666 | H20: =C20/C19-1 -> 0.025058729 | I20: =D20/D19-1 -> 0.0086841803 | K20: Volatility | L20: =_xlfn.STDEV.S(G7:G254) -> 0.017004557 | M20: =_xlfn.STDEV.S(H7:H254) -> 0.020791509 | N20: =_xlfn.STDEV.S(I7:I254) -> 0.017746965 | T20: 14 | U20: -0.035640631 | W20: 15 | X20: =_xlfn.NORM.S.INV(RAND()) -> 0.29331798 | Y20: =_xlfn.NORM.S.INV(RAND()) -> 1.9901075 | Z20: =_xlfn.NORM.S.INV(RAND()) -> -0.50580888 | AB20: 15 | AC20: =SUMPRODUCT($Q$24:$S$24,X20:Z20) -> 0.29331798 | AD20: =SUMPRODUCT($Q$25:$S$25,X20:Z20) -> 1.2358434 | AE20: =SUMPRODUCT($Q$26:$S$26,X20:Z20) -> 0.5320706 | AG20: 14 | AH20: =$L$21*EXP(($L$19-(($L$20^2)/2))*(1/252)+$L$20*AC20) -> 310.989 | AI20: =$M$21*EXP(($M$19-(($M$20^2)/2))*(1/252)+$M$20*AD20) -> 168.53635 | AJ20: =$N$21*EXP(($N$19-(($N$20^2)/2))*(1/252)+$N$20*AE20) -> 53.533338 | AL20: 15 | AM20: =AH20/$AH$2-1 -> 0.0050058086 | AN20: =AI20/$AI$2-1 -> 0.026034053 | AO20: =AJ20/$AJ$2-1 -> 0.0094916023 | AP20: =SUMPRODUCT($P$6:$R$6,AM20:AO20) -> 0.014762845
A21: 45618 | B21: =Data!B18 -> 243.39754 | C21: =Data!H18 -> 131.02126 | D21: =Data!N18 -> 45.919369 | F21: 45618 | G21: =B21/B20-1 -> 0.01548459 | H21: =C21/C20-1 -> -0.0022224714 | I21: =D21/D20-1 -> 0.011622983 | K21: S0 (As on 30/10/2025) | L21: =B254 -> 309.44 | M21: =C254 -> 164.25999 | N21: =D254 -> 53.029999 | T21: 15 | U21: -0.035590468 | W21: 16 | X21: =_xlfn.NORM.S.INV(RAND()) -> 1.8148958 | Y21: =_xlfn.NORM.S.INV(RAND()) -> 0.31294836 | Z21: =_xlfn.NORM.S.INV(RAND()) -> 2.6567453 | AB21: 16 | AC21: =SUMPRODUCT($Q$24:$S$24,X21:Z21) -> 1.8148958 | AD21: =SUMPRODUCT($Q$25:$S$25,X21:Z21) -> 1.7334823 | AE21: =SUMPRODUCT($Q$26:$S$26,X21:Z21) -> 2.9160945 | AG21: 16 | AH21: =$L$21*EXP(($L$19-(($L$20^2)/2))*(1/252)+$L$20*AC21) -> 319.14045 | AI21: =$M$21*EXP(($M$19-(($M$20^2)/2))*(1/252)+$M$20*AD21) -> 170.28919 | AJ21: =$N$21*EXP(($N$19-(($N$20^2)/2))*(1/252)+$N$20*AE21) -> 55.846888 | AL21: 16 | AM21: =AH21/$AH$2-1 -> 0.031348407 | AN21: =AI21/$AI$2-1 -> 0.036705191 | AO21: =AJ21/$AJ$2-1 -> 0.053118779 | AP21: =SUMPRODUCT($P$6:$R$6,AM21:AO21) -> 0.040022232
A22: 45621 | B22: =Data!B19 -> 245.10147 | C22: =Data!H19 -> 130.0193 | D22: =Data!N19 -> 46.407871 | F22: 45621 | G22: =B22/B21-1 -> 0.0070006202 | H22: =C22/C21-1 -> -0.0076472563 | I22: =D22/D21-1 -> 0.010638267 | P22: Cholesky Decomposition | T22: 16 | U22: -0.03556965 | W22: 17 | X22: =_xlfn.NORM.S.INV(RAND()) -> 1.2626243 | Y22: =_xlfn.NORM.S.INV(RAND()) -> -0.60955334 | Z22: =_xlfn.NORM.S.INV(RAND()) -> 0.20261762 | AB22: 17 | AC22: =SUMPRODUCT($Q$24:$S$24,X22:Z22) -> 1.2626243 | AD22: =SUMPRODUCT($Q$25:$S$25,X22:Z22) -> 0.7983552 | AE22: =SUMPRODUCT($Q$26:$S$26,X22:Z22) -> 0.9651543 | AG22: 17 | AH22: =$L$21*EXP(($L$19-(($L$20^2)/2))*(1/252)+$L$20*AC22) -> 316.15739 | AI22: =$M$21*EXP(($M$19-(($M$20^2)/2))*(1/252)+$M$20*AD22) -> 167.01029 | AJ22: =$N$21*EXP(($N$19-(($N$20^2)/2))*(1/252)+$N$20*AE22) -> 53.946377 | AL22: 17 | AM22: =AH22/$AH$2-1 -> 0.021708214 | AN22: =AI22/$AI$2-1 -> 0.016743524 | AO22: =AJ22/$AJ$2-1 -> 0.017280369 | AP22: =SUMPRODUCT($P$6:$R$6,AM22:AO22) -> 0.018393984
A23: 45622 | B23: =Data!B20 -> 244.78809 | C23: =Data!H20 -> 127.70413 | D23: =Data!N20 -> 46.652122 | F23: 45622 | G23: =B23/B22-1 -> -0.0012785929 | H23: =C23/C22-1 -> -0.017806358 | I23: =D23/D22-1 -> 0.0052631428 | K23: Correlation | L23: JPM | M23: MS | N23: BAC | Q23: JPM | R23: MS | S23: BAC | T23: 17 | U23: -0.035280042 | W23: 18 | X23: =_xlfn.NORM.S.INV(RAND()) -> -0.10026167 | Y23: =_xlfn.NORM.S.INV(RAND()) -> 0.44189107 | Z23: =_xlfn.NORM.S.INV(RAND()) -> -0.1442059 | AB23: 18 | AC23: =SUMPRODUCT($Q$24:$S$24,X23:Z23) -> -0.10026167 | AD23: =SUMPRODUCT($Q$25:$S$25,X23:Z23) -> 0.13049189 | AE23: =SUMPRODUCT($Q$26:$S$26,X23:Z23) -> -0.033040464 | AG23: 18 | AH23: =$L$21*EXP(($L$19-(($L$20^2)/2))*(1/252)+$L$20*AC23) -> 308.91461 | AI23: =$M$21*EXP(($M$19-(($M$20^2)/2))*(1/252)+$M$20*AD23) -> 164.70723 | AJ23: =$N$21*EXP(($N$19-(($N$20^2)/2))*(1/252)+$N$20*AE23) -> 52.999136 | AL23: 18 | AM23: =AH23/$AH$2-1 -> -0.0016978835 | AN23: =AI23/$AI$2-1 -> 0.0027227106 | AO23: =AJ23/$AJ$2-1 -> -0.0005819966 | AP23: =SUMPRODUCT($P$6:$R$6,AM23:AO23) -> 0.00040512021
A24: 45623 | B24: =Data!B21 -> 244.6118 | C24: =Data!H21 -> 127.63606 | D24: =Data!N21 -> 46.671661 | F24: 45623 | G24: =B24/B23-1 -> -0.00072015266 | H24: =C24/C23-1 -> -0.00053302471 | I24: =D24/D23-1 -> 0.0004188208 | K24: JPM | L24: 1 | M24: =L25 -> 0.87017677 | N24: =L26 -> 0.81622686 | P24: JPM | Q24: =SQRT(L24) -> 1 | R24: 0 | S24: 0 | T24: 18 | U24: -0.035094204 | W24: 19 | X24: =_xlfn.NORM.S.INV(RAND()) -> 1.1700651 | Y24: =_xlfn.NORM.S.INV(RAND()) -> 0.81121809 | Z24: =_xlfn.NORM.S.INV(RAND()) -> -0.76990449 | AB24: 19 | AC24: =SUMPRODUCT($Q$24:$S$24,X24:Z24) -> 1.1700651 | AD24: =SUMPRODUCT($Q$25:$S$25,X24:Z24) -> 1.4178828 | AE24: =SUMPRODUCT($Q$26:$S$26,X24:Z24) -> 0.78823413 | AG24: 19 | AH24: =$L$21*EXP(($L$19-(($L$20^2)/2))*(1/252)+$L$20*AC24) -> 315.66017 | AI24: =$M$21*EXP(($M$19-(($M$20^2)/2))*(1/252)+$M$20*AD24) -> 169.17545 | AJ24: =$N$21*EXP(($N$19-(($N$20^2)/2))*(1/252)+$N$20*AE24) -> 53.777262 | AL24: 19 | AM24: =AH24/$AH$2-1 -> 0.020101384 | AN24: =AI24/$AI$2-1 -> 0.029924821 | AO24: =AJ24/$AJ$2-1 -> 0.014091325 | AP24: =SUMPRODUCT($P$6:$R$6,AM24:AO24) -> 0.022227741
A25: 45625 | B25: =Data!B22 -> 244.54327 | C25: =Data!H22 -> 128.02515 | D25: =Data!N22 -> 46.417641 | F25: 45625 | G25: =B25/B24-1 -> -0.00028014683 | H25: =C25/C24-1 -> 0.003048385 | I25: =D25/D24-1 -> -0.005442718 | K25: MS | L25: 0.87017677 | M25: 1 | N25: =M26 -> 0.84628077 | P25: MS | Q25: =L25/Q24 -> 0.87017677 | R25: =SQRT(M25-Q25^2) -> 0.49273968 | S25: 0 | T25: 19 | U25: -0.034932628 | W25: 20 | X25: =_xlfn.NORM.S.INV(RAND()) -> 0.1335854 | Y25: =_xlfn.NORM.S.INV(RAND()) -> -0.99720979 | Z25: =_xlfn.NORM.S.INV(RAND()) -> -0.6686052 | AB25: 20 | AC25: =SUMPRODUCT($Q$24:$S$24,X25:Z25) -> 0.1335854 | AD25: =SUMPRODUCT($Q$25:$S$25,X25:Z25) -> -0.37512192 | AE25: =SUMPRODUCT($Q$26:$S$26,X25:Z25) -> -0.5055679 | AG25: 20 | AH25: =$L$21*EXP(($L$19-(($L$20^2)/2))*(1/252)+$L$20*AC25) -> 310.14544 | AI25: =$M$21*EXP(($M$19-(($M$20^2)/2))*(1/252)+$M$20*AD25) -> 162.98482 | AJ25: =$N$21*EXP(($N$19-(($N$20^2)/2))*(1/252)+$N$20*AE25) -> 52.556547 | AL25: 20 | AM25: =AH25/$AH$2-1 -> 0.002279734 | AN25: =AI25/$AI$2-1 -> -0.0077631728 | AO25: =AJ25/$AJ$2-1 -> -0.0089280002 | AP25: =SUMPRODUCT($P$6:$R$6,AM25:AO25) -> -0.005099749
A26: 45628 | B26: =Data!B23 -> 241.14522 | C26: =Data!H23 -> 127.46094 | D26: =Data!N23 -> 45.958447 | F26: 45628 | G26: =B26/B25-1 -> -0.01389552 | H26: =C26/C25-1 -> -0.0044070169 | I26: =D26/D25-1 -> -0.0098926653 | K26: BAC | L26: 0.81622686 | M26: 0.84628077 | N26: 1 | P26: BAC | Q26: =L26/Q24 -> 0.81622686 | R26: =(M26-Q26*Q25)/R25 -> 0.27604661 | S26: =SQRT(N26-Q26^2-R26^2) -> 0.5075155 | T26: 20 | U26: -0.034628336 | W26: 21 | X26: =_xlfn.NORM.S.INV(RAND()) -> -0.28241806 | Y26: =_xlfn.NORM.S.INV(RAND()) -> -1.6897631 | Z26: =_xlfn.NORM.S.INV(RAND()) -> -1.5764303 | AB26: 21 | AC26: =SUMPRODUCT($Q$24:$S$24,X26:Z26) -> -0.28241806 | AD26: =SUMPRODUCT($Q$25:$S$25,X26:Z26) -> -1.078367 | AE26: =SUMPRODUCT($Q$26:$S$26,X26:Z26) -> -1.4970334 | AG26: 21 | AH26: =$L$21*EXP(($L$19-(($L$20^2)/2))*(1/252)+$L$20*AC26) -> 307.95923 | AI26: =$M$21*EXP(($M$19-(($M$20^2)/2))*(1/252)+$M$20*AD26) -> 160.61907 | AJ26: =$N$21*EXP(($N$19-(($N$20^2)/2))*(1/252)+$N$20*AE26) -> 51.639876 | AL26: 21 | AM26: =AH26/$AH$2-1 -> -0.004785329 | AN26: =AI26/$AI$2-1 -> -0.022165639 | AO26: =AJ26/$AJ$2-1 -> -0.026213887 | AP26: =SUMPRODUCT($P$6:$R$6,AM26:AO26) -> -0.01816602
A27: 45629 | B27: =Data!B24 -> 239.74486 | C27: =Data!H24 -> 126.88702 | D27: =Data!N24 -> 45.743504 | F27: 45629 | G27: =B27/B26-1 -> -0.0058071237 | H27: =C27/C26-1 -> -0.0045027223 | I27: =D27/D26-1 -> -0.0046768973 | T27: 21 | U27: -0.034504668 | W27: 22 | X27: =_xlfn.NORM.S.INV(RAND()) -> -0.42853886 | Y27: =_xlfn.NORM.S.INV(RAND()) -> -0.5186041 | Z27: =_xlfn.NORM.S.INV(RAND()) -> -1.3451219 | AB27: 22 | AC27: =SUMPRODUCT($Q$24:$S$24,X27:Z27) -> -0.42853886 | AD27: =SUMPRODUCT($Q$25:$S$25,X27:Z27) -> -0.62844138 | AE27: =SUMPRODUCT($Q$26:$S$26,X27:Z27) -> -1.1756141 | AG27: 22 | AH27: =$L$21*EXP(($L$19-(($L$20^2)/2))*(1/252)+$L$20*AC27) -> 307.19499 | AI27: =$M$21*EXP(($M$19-(($M$20^2)/2))*(1/252)+$M$20*AD27) -> 162.12865 | AJ27: =$N$21*EXP(($N$19-(($N$20^2)/2))*(1/252)+$N$20*AE27) -> 51.935283 | AL27: 22 | AM27: =AH27/$AH$2-1 -> -0.0072550888 | AN27: =AI27/$AI$2-1 -> -0.01297544 | AO27: =AJ27/$AJ$2-1 -> -0.020643327 | AP27: =SUMPRODUCT($P$6:$R$6,AM27:AO27) -> -0.013559701
A28: 45630 | B28: =Data!B25 -> 238.35426 | C28: =Data!H25 -> 126.44928 | D28: =Data!N25 -> 45.303852 | F28: 45630 | G28: =B28/B27-1 -> -0.0058003099 | H28: =C28/C27-1 -> -0.0034498133 | I28: =D28/D27-1 -> -0.0096112334 | T28: 22 | U28: -0.03434604 | W28: 23 | X28: =_xlfn.NORM.S.INV(RAND()) -> -0.76954026 | Y28: =_xlfn.NORM.S.INV(RAND()) -> -0.38087636 | Z28: =_xlfn.NORM.S.INV(RAND()) -> -1.7017973 | AB28: 23 | AC28: =SUMPRODUCT($Q$24:$S$24,X28:Z28) -> -0.76954026 | AD28: =SUMPRODUCT($Q$25:$S$25,X28:Z28) -> -0.85730896 | AE28: =SUMPRODUCT($Q$26:$S$26,X28:Z28) -> -1.5969475 | AG28: 23 | AH28: =$L$21*EXP(($L$19-(($L$20^2)/2))*(1/252)+$L$20*AC28) -> 305.41885 | AI28: =$M$21*EXP(($M$19-(($M$20^2)/2))*(1/252)+$M$20*AD28) -> 161.35899 | AJ28: =$N$21*EXP(($N$19-(($N$20^2)/2))*(1/252)+$N$20*AE28) -> 51.548391 | AL28: 23 | AM28: =AH28/$AH$2-1 -> -0.01299494 | AN28: =AI28/$AI$2-1 -> -0.017661042 | AO28: =AJ28/$AJ$2-1 -> -0.027939049 | AP28: =SUMPRODUCT($P$6:$R$6,AM28:AO28) -> -0.019344613
A29: 45631 | B29: =Data!B26 -> 240.39117 | C29: =Data!H26 -> 126.77029 | D29: =Data!N26 -> 45.919369 | F29: 45631 | G29: =B29/B28-1 -> 0.0085457293 | H29: =C29/C28-1 -> 0.0025386812 | I29: =D29/D28-1 -> 0.013586409 | T29: 23 | U29: -0.033368566 | W29: 24 | X29: =_xlfn.NORM.S.INV(RAND()) -> 0.043734375 | Y29: =_xlfn.NORM.S.INV(RAND()) -> 0.054389208 | Z29: =_xlfn.NORM.S.INV(RAND()) -> 0.82405296 | AB29: 24 | AC29: =SUMPRODUCT($Q$24:$S$24,X29:Z29) -> 0.043734375 | AD29: =SUMPRODUCT($Q$25:$S$25,X29:Z29) -> 0.064856358 | AE29: =SUMPRODUCT($Q$26:$S$26,X29:Z29) -> 0.46893078 | AG29: 24 | AH29: =$L$21*EXP(($L$19-(($L$20^2)/2))*(1/252)+$L$20*AC29) -> 309.67194 | AI29: =$M$21*EXP(($M$19-(($M$20^2)/2))*(1/252)+$M$20*AD29) -> 164.48261 | AJ29: =$N$21*EXP(($N$19-(($N$20^2)/2))*(1/252)+$N$20*AE29) -> 53.473386 | AL29: 24 | AM29: =AH29/$AH$2-1 -> 0.00074954321 | AN29: =AI29/$AI$2-1 -> 0.0013552666 | AO29: =AJ29/$AJ$2-1 -> 0.0083610598 | AP29: =SUMPRODUCT($P$6:$R$6,AM29:AO29) -> 0.0032752875
A30: 45632 | B30: =Data!B27 -> 242.23221 | C30: =Data!H27 -> 126.4201 | D30: =Data!N27 -> 45.929192 | F30: 45632 | G30: =B30/B29-1 -> 0.0076584922 | H30: =C30/C29-1 -> -0.0027623917 | I30: =D30/D29-1 -> 0.00021391508 | T30: 24 | U30: -0.033211525 | W30: 25 | X30: =_xlfn.NORM.S.INV(RAND()) -> 1.495068 | Y30: =_xlfn.NORM.S.INV(RAND()) -> -1.2411241 | Z30: =_xlfn.NORM.S.INV(RAND()) -> 1.253734 | AB30: 25 | AC30: =SUMPRODUCT($Q$24:$S$24,X30:Z30) -> 1.495068 | AD30: =SUMPRODUCT($Q$25:$S$25,X30:Z30) -> 0.68942231 | AE30: =SUMPRODUCT($Q$26:$S$26,X30:Z30) -> 1.513996 | AG30: 25 | AH30: =$L$21*EXP(($L$19-(($L$20^2)/2))*(1/252)+$L$20*AC30) -> 317.40951 | AI30: =$M$21*EXP(($M$19-(($M$20^2)/2))*(1/252)+$M$20*AD30) -> 166.63246 | AJ30: =$N$21*EXP(($N$19-(($N$20^2)/2))*(1/252)+$N$20*AE30) -> 54.474397 | AL30: 25 | AM30: =AH30/$AH$2-1 -> 0.025754611 | AN30: =AI30/$AI$2-1 -> 0.014443329 | AO30: =AJ30/$AJ$2-1 -> 0.027237371 | AP30: =SUMPRODUCT($P$6:$R$6,AM30:AO30) -> 0.021674926
A31: 45635 | B31: =Data!B28 -> 238.75578 | C31: =Data!H28 -> 125.07769 | D31: =Data!N28 -> 45.103943 | F31: 45635 | G31: =B31/B30-1 -> -0.014351622 | H31: =C31/C30-1 -> -0.010618682 | I31: =D31/D30-1 -> -0.017967848 | T31: 25 | U31: -0.033130457 | W31: 26 | X31: =_xlfn.NORM.S.INV(RAND()) -> 0.21189469 | Y31: =_xlfn.NORM.S.INV(RAND()) -> -1.4050476 | Z31: =_xlfn.NORM.S.INV(RAND()) -> -0.9372005 | AB31: 26 | AC31: =SUMPRODUCT($Q$24:$S$24,X31:Z31) -> 0.21189469 | AD31: =SUMPRODUCT($Q$25:$S$25,X31:Z31) -> -0.50793689 | AE31: =SUMPRODUCT($Q$26:$S$26,X31:Z31) -> -0.69054829 | AG31: 26 | AH31: =$L$21*EXP(($L$19-(($L$20^2)/2))*(1/252)+$L$20*AC31) -> 310.55871 | AI31: =$M$21*EXP(($M$19-(($M$20^2)/2))*(1/252)+$M$20*AD31) -> 162.53537 | AJ31: =$N$21*EXP(($N$19-(($N$20^2)/2))*(1/252)+$N$20*AE31) -> 52.384295 | AL31: 26 | AM31: =AH31/$AH$2-1 -> 0.0036152736 | AN31: =AI31/$AI$2-1 -> -0.010499379 | AO31: =AJ31/$AJ$2-1 -> -0.012176197 | AP31: =SUMPRODUCT($P$6:$R$6,AM31:AO31) -> -0.0067680287
A32: 45636 | B32: =Data!B29 -> 237.82547 | C32: =Data!H29 -> 123.33644 | D32: =Data!N29 -> 44.946751 | F32: 45636 | G32: =B32/B31-1 -> -0.003896505 | H32: =C32/C31-1 -> -0.01392134 | I32: =D32/D31-1 -> -0.0034851106 | T32: 26 | U32: -0.033056842 | W32: 27 | X32: =_xlfn.NORM.S.INV(RAND()) -> -0.053445157 | Y32: =_xlfn.NORM.S.INV(RAND()) -> 0.23483933 | Z32: =_xlfn.NORM.S.INV(RAND()) -> -0.045286561 | AB32: 27 | AC32: =SUMPRODUCT($Q$24:$S$24,X32:Z32) -> -0.053445157 | AD32: =SUMPRODUCT($Q$25:$S$25,X32:Z32) -> 0.06920792 | AE32: =SUMPRODUCT($Q$26:$S$26,X32:Z32) -> -0.0017804042 | AG32: 27 | AH32: =$L$21*EXP(($L$19-(($L$20^2)/2))*(1/252)+$L$20*AC32) -> 309.16063 | AI32: =$M$21*EXP(($M$19-(($M$20^2)/2))*(1/252)+$M$20*AD32) -> 164.49749 | AJ32: =$N$21*EXP(($N$19-(($N$20^2)/2))*(1/252)+$N$20*AE32) -> 53.028546 | AL32: 27 | AM32: =AH32/$AH$2-1 -> -0.00090282471 | AN32: =AI32/$AI$2-1 -> 0.0014458688 | AO32: =AJ32/$AJ$2-1 -> -2.7394483e-05 | AP32: =SUMPRODUCT($P$6:$R$6,AM32:AO32) -> 0.00029928177
A33: 45637 | B33: =Data!B30 -> 238.48158 | C33: =Data!H30 -> 124.11465 | D33: =Data!N30 -> 45.270958 | F33: 45637 | G33: =B33/B32-1 -> 0.002758799 | H33: =C33/C32-1 -> 0.0063096183 | I33: =D33/D32-1 -> 0.0072131422 | T33: 27 | U33: -0.032852035 | W33: 28 | X33: =_xlfn.NORM.S.INV(RAND()) -> -0.84180415 | Y33: =_xlfn.NORM.S.INV(RAND()) -> 0.59836496 | Z33: =_xlfn.NORM.S.INV(RAND()) -> 0.91509528 | AB33: 28 | AC33: =SUMPRODUCT($Q$24:$S$24,X33:Z33) -> -0.84180415 | AD33: =SUMPRODUCT($Q$25:$S$25,X33:Z33) -> -0.43768026 | AE33: =SUMPRODUCT($Q$26:$S$26,X33:Z33) -> -0.057501501 | AG33: 28 | AH33: =$L$21*EXP(($L$19-(($L$20^2)/2))*(1/252)+$L$20*AC33) -> 305.04378 | AI33: =$M$21*EXP(($M$19-(($M$20^2)/2))*(1/252)+$M$20*AD33) -> 162.77296 | AJ33: =$N$21*EXP(($N$19-(($N$20^2)/2))*(1/252)+$N$20*AE33) -> 52.976133 | AL33: 28 | AM33: =AH33/$AH$2-1 -> -0.014207042 | AN33: =AI33/$AI$2-1 -> -0.0090529187 | AO33: =AJ33/$AJ$2-1 -> -0.001015759 | AP33: =SUMPRODUCT($P$6:$R$6,AM33:AO33) -> -0.0081880078
A34: 45638 | B34: =Data!B31 -> 236.52306 | C34: =Data!H31 -> 124.42593 | D34: =Data!N31 -> 45.270958 | F34: 45638 | G34: =B34/B33-1 -> -0.0082124858 | H34: =C34/C33-1 -> 0.0025079981 | I34: =D34/D33-1 -> 0 | T34: 28 | U34: -0.032765791 | W34: 29 | X34: =_xlfn.NORM.S.INV(RAND()) -> -1.0159947 | Y34: =_xlfn.NORM.S.INV(RAND()) -> 1.0873757 | Z34: =_xlfn.NORM.S.INV(RAND()) -> -1.0812195 | AB34: 29 | AC34: =SUMPRODUCT($Q$24:$S$24,X34:Z34) -> -1.0159947 | AD34: =SUMPRODUCT($Q$25:$S$25,X34:Z34) -> -0.34830185 | AE34: =SUMPRODUCT($Q$26:$S$26,X34:Z34) -> -1.0778515 | AG34: 29 | AH34: =$L$21*EXP(($L$19-(($L$20^2)/2))*(1/252)+$L$20*AC34) -> 304.14156 | AI34: =$M$21*EXP(($M$19-(($M$20^2)/2))*(1/252)+$M$20*AD34) -> 163.07573 | AJ34: =$N$21*EXP(($N$19-(($N$20^2)/2))*(1/252)+$N$20*AE34) -> 52.025469 | AL34: 29 | AM34: =AH34/$AH$2-1 -> -0.017122674 | AN34: =AI34/$AI$2-1 -> -0.0072097178 | AO34: =AJ34/$AJ$2-1 -> -0.018942679 | AP34: =SUMPRODUCT($P$6:$R$6,AM34:AO34) -> -0.013703493
A35: 45639 | B35: =Data!B32 -> 234.966 | C35: =Data!H32 -> 123.92982 | D35: =Data!N32 -> 44.868149 | F35: 45639 | G35: =B35/B34-1 -> -0.0065830902 | H35: =C35/C34-1 -> -0.0039871223 | I35: =D35/D34-1 -> -0.0088977384 | T35: 29 | U35: -0.032561852 | W35: 30 | X35: =_xlfn.NORM.S.INV(RAND()) -> -0.18496037 | Y35: =_xlfn.NORM.S.INV(RAND()) -> -1.8087484 | Z35: =_xlfn.NORM.S.INV(RAND()) -> 1.7568948 | AB35: 30 | AC35: =SUMPRODUCT($Q$24:$S$24,X35:Z35) -> -0.18496037 | AD35: =SUMPRODUCT($Q$25:$S$25,X35:Z35) -> -1.0521903 | AE35: =SUMPRODUCT($Q$26:$S$26,X35:Z35) -> 0.24138283 | AG35: 30 | AH35: =$L$21*EXP(($L$19-(($L$20^2)/2))*(1/252)+$L$20*AC35) -> 308.47001 | AI35: =$M$21*EXP(($M$19-(($M$20^2)/2))*(1/252)+$M$20*AD35) -> 160.70651 | AJ35: =$N$21*EXP(($N$19-(($N$20^2)/2))*(1/252)+$N$20*AE35) -> 53.25788 | AL35: 30 | AM35: =AH35/$AH$2-1 -> -0.0031346672 | AN35: =AI35/$AI$2-1 -> -0.021633306 | AO35: =AJ35/$AJ$2-1 -> 0.0042972211 | AP35: =SUMPRODUCT($P$6:$R$6,AM35:AO35) -> -0.0083045563
A36: 45642 | B36: =Data!B33 -> 234.61346 | C36: =Data!H33 -> 125.51543 | D36: =Data!N33 -> 44.671665 | F36: 45642 | G36: =B36/B35-1 -> -0.0015003833 | H36: =C36/C35-1 -> 0.012794352 | I36: =D36/D35-1 -> -0.0043791335 | T36: 30 | U36: -0.032426333 | W36: 31 | X36: =_xlfn.NORM.S.INV(RAND()) -> -1.4390889 | Y36: =_xlfn.NORM.S.INV(RAND()) -> 1.416605 | Z36: =_xlfn.NORM.S.INV(RAND()) -> -0.31668877 | AB36: 31 | AC36: =SUMPRODUCT($Q$24:$S$24,X36:Z36) -> -1.4390889 | AD36: =SUMPRODUCT($Q$25:$S$25,X36:Z36) -> -0.5542442 | AE36: =SUMPRODUCT($Q$26:$S$26,X36:Z36) -> -0.94429843 | AG36: 31 | AH36: =$L$21*EXP(($L$19-(($L$20^2)/2))*(1/252)+$L$20*AC36) -> 301.96126 | AI36: =$M$21*EXP(($M$19-(($M$20^2)/2))*(1/252)+$M$20*AD36) -> 162.37895 | AJ36: =$N$21*EXP(($N$19-(($N$20^2)/2))*(1/252)+$N$20*AE36) -> 52.148924 | AL36: 31 | AM36: =AH36/$AH$2-1 -> -0.024168636 | AN36: =AI36/$AI$2-1 -> -0.011451611 | AO36: =AJ36/$AJ$2-1 -> -0.016614657 | AP36: =SUMPRODUCT($P$6:$R$6,AM36:AO36) -> -0.016815633
A37: 45643 | B37: =Data!B34 -> 233.41876 | C37: =Data!H34 -> 124.26057 | D37: =Data!N34 -> 44.259041 | F37: 45643 | G37: =B37/B36-1 -> -0.0050922148 | H37: =C37/C36-1 -> -0.0099976549 | I37: =D37/D36-1 -> -0.0092368251 | T37: 31 | U37: -0.032307944 | W37: 32 | X37: =_xlfn.NORM.S.INV(RAND()) -> -0.74822076 | Y37: =_xlfn.NORM.S.INV(RAND()) -> -0.91940395 | Z37: =_xlfn.NORM.S.INV(RAND()) -> -0.66079953 | AB37: 32 | AC37: =SUMPRODUCT($Q$24:$S$24,X37:Z37) -> -0.74822076 | AD37: =SUMPRODUCT($Q$25:$S$25,X37:Z37) -> -1.1041111 | AE37: =SUMPRODUCT($Q$26:$S$26,X37:Z37) -> -1.1998822 | AG37: 32 | AH37: =$L$21*EXP(($L$19-(($L$20^2)/2))*(1/252)+$L$20*AC37) -> 305.52959 | AI37: =$M$21*EXP(($M$19-(($M$20^2)/2))*(1/252)+$M$20*AD37) -> 160.53312 | AJ37: =$N$21*EXP(($N$19-(($N$20^2)/2))*(1/252)+$N$20*AE37) -> 51.91292 | AL37: 32 | AM37: =AH37/$AH$2-1 -> -0.012637057 | AN37: =AI37/$AI$2-1 -> -0.022688895 | AO37: =AJ37/$AJ$2-1 -> -0.021065032 | AP37: =SUMPRODUCT($P$6:$R$6,AM37:AO37) -> -0.019186185
A38: 45644 | B38: =Data!B35 -> 225.59441 | C38: =Data!H35 -> 117.74306 | D38: =Data!N35 -> 42.736252 | F38: 45644 | G38: =B38/B37-1 -> -0.033520682 | H38: =C38/C37-1 -> -0.052450344 | I38: =D38/D37-1 -> -0.034406281 | T38: 32 | U38: -0.032201231 | W38: 33 | X38: =_xlfn.NORM.S.INV(RAND()) -> -0.78533083 | Y38: =_xlfn.NORM.S.INV(RAND()) -> 0.83358202 | Z38: =_xlfn.NORM.S.INV(RAND()) -> -0.26932863 | AB38: 33 | AC38: =SUMPRODUCT($Q$24:$S$24,X38:Z38) -> -0.78533083 | AD38: =SUMPRODUCT($Q$25:$S$25,X38:Z38) -> -0.2726377 | AE38: =SUMPRODUCT($Q$26:$S$26,X38:Z38) -> -0.54758907 | AG38: 33 | AH38: =$L$21*EXP(($L$19-(($L$20^2)/2))*(1/252)+$L$20*AC38) -> 305.33685 | AI38: =$M$21*EXP(($M$19-(($M$20^2)/2))*(1/252)+$M$20*AD38) -> 163.33247 | AJ38: =$N$21*EXP(($N$19-(($N$20^2)/2))*(1/252)+$N$20*AE38) -> 52.517368 | AL38: 33 | AM38: =AH38/$AH$2-1 -> -0.013259927 | AN38: =AI38/$AI$2-1 -> -0.005646659 | AO38: =AJ38/$AJ$2-1 -> -0.009666815 | AP38: =SUMPRODUCT($P$6:$R$6,AM38:AO38) -> -0.0091366861
